{
    "name": "py_error_recover",

    "id": "py_error_recover",
    "language": "python2",
    "code": "def run():\n\ttry: clotho.run('py_die_run', [])\n\texcept ClothoError as e: return 'caught ClothoError: {}'.format(e.args[0])\n\traise RuntimeException('this is very bad; please fix me')"
}
